Workbook
Name QryTeamCCOQJuly: TeamToQueueMap!$A$1:$C$859
Name UniqueCCOQueueCodes: Unique_CCO_Queue_Code_Update!$B$1:$I$439
Name UniqueCCOQueueCodes: UniqueCCOQueueCodes!$A$1:$I$553

Sheet Sheet1
A3: Domain | B3: LOB Alignment | C3: epicenter_cco_queue_code | D3: epicenter_cco_queue_desc | E3: Flag
A4: All | B4: All | C4: AO06 | D4: APJ Upsell-Operations Multi | E4: Y | F4: #N/A
C5: ES01 | D5: EMEA Static Central | E5: Y | F5: 1
C6: RR03 | D6: Support Ops ROLA | E6: Y | F6: #N/A
A7: CTE | B7: CTE | C7: CT11 | D7: CTE ANZ | E7: Y | F7: 4
C8: CT13 | D8: CTE CCC | E8: Y | F8: 2
C9: CT14 | D9: CTE IND | E9: Y | F9: 8
C10: CT15 | D10: CTE JPN | E10: Y | F10: #N/A
C11: CT16 | D11: CTE KOR | E11: Y | F11: #N/A
C12: CT18 | D12: CTE SA | E12: Y | F12: 6
C13: CT95 | D13: CTE NW IND | E13: Y | F13: 2
C14: CT96 | D14: CTE Storage IND | E14: Y | F14: 2
C15: CTE2 | D15: NA CTE Server | E15: Y | F15: 12
C16: CTE3 | D16: EMEA SERVER CTE | E16: Y | F16: 3
C17: CTE4 | D17: EMEA MODULAR CTE | E17: Y | F17: 9
C18: CTE6 | D18: NA CTE Storage | E18: Y | F18: #N/A
C19: GCTE | D19: CTE Global English | E19: Y | F19: #N/A
C20: PS03 | D20: Brazil ESG CTE | E20: Y | F20: 6
C21: SS03 | D21: MMCLA ESG CTE | E21: Y | F21: 3
A22: DPD | B22: Avamar | C22: AP12 | D22: APJ DPD AVAMAR Chinese | E22: Y | F22: 18
C23: GH01 | D23: GLOBAL DPD AVAMAR | E23: Y | F23: 60
C24: HE36 | D24: HES Global AVAMAR | E24: Y | F24: #N/A
C25: HEG4 | D25: AMER English Avamar | E25: Y | F25: #N/A
C26: HEG8 | D26: EMEA English Avamar | E26: Y | F26: #N/A
C27: IS11 | D27: APJ DPD AVAMAR | E27: Y | F27: 22
C28: IS38 | D28: EMEA DPD AVAMAR | E28: Y | F28: 29
C29: IS65 | D29: India DPD AVAMAR | E29: Y | F29: #N/A
C30: IS92 | D30: LATAM DPD AVAMAR | E30: Y | F30: 19
C31: IU20 | D31: NAMER DPD AVAMAR | E31: Y | F31: 77.8
B32: Cloudboost | C32: GH02 | D32: GLOBAL DPD Cloudboost | E32: Y | F32: #N/A
C33: HE44 | D33: HES Global Cloudboost | E33: Y | F33: #N/A
B34: DataDomain | C34: AP14 | D34: APJ DPD DataDomain Chinese | E34: Y | F34: 14
C35: GH03 | D35: GLOBAL DPD DataDomain | E35: Y | F35: 44.8
C36: HE38 | D36: HES Global DATADomain | E36: Y | F36: #N/A
C37: HEH6 | D37: AMER English DataDomain | E37: Y | F37: #N/A
C38: HEJ1 | D38: EMEA English DataDomain | E38: Y | F38: #N/A
C39: IS15 | D39: APJ DPD DataDomain | E39: Y | F39: 18
C40: IS42 | D40: EMEA DPD DataDomain | E40: Y | F40: 37.5769
C41: IS69 | D41: India DPD DataDomain | E41: Y | F41: #N/A
C42: IS96 | D42: LATAM DPD DataDomain | E42: Y | F42: 11
...

Sheet Sheet8
A1: Status | B1: (All)
A3: Row Labels | D3: Row Labels | E3: Count of epicenter_cco_queue_desc
A4: AM02 | D4: Active | E4: 199
A5: AM04 | D5: Inactive | E5: 406
A6: AM05 | D6: Grand Total | E6: 605
A7: AM08
A8: AN02
A9: AN03
A10: AO06
A11: AO11
A12: AO14
A13: AP10
A14: AP11
A15: AP12
A16: AP13
A17: AP14
A18: AP15
... A615: Grand Total

Sheet UniqueCCOQueueCodes
A1: epicenter_cco_queue_code | B1: epicenter_cco_queue_desc | C1: L5 | D1: Domain | E1: LOB Alignment | F1: Flag | G1: GS Flag | H1: Resource Region | I1: Resource Sub Region | J1: Utilization | K1: Attrition | L1: Reason | M1: Coverage | N1: Queue Type | O1: Queue Description | P1: Capacity Planner | Q1: Business Owner | R1: Coverage HC | S1: Manual Adj% | T1: HES/ESG | U1: H&T Leadtime | V1: Status | W1: HC_Week 3 | X1: Scope to Merge | Y1: Coverage Time | Z1: Coverage Days | AA1: Comment | AB1: Language | AC1: Scheduler
A2: CV02 | B2: HCS AMER Converged Infrastructure | C2: D'Arcy, Mark | D2: GNCS | E2: Powerflex | F2: Y | G2: Combined | H2: NAMER | J2: 0.648 | K2: 0.020441446 | M2: 12/7 | N2: L1 | O2: =A2&"_"&B2 -> CV02_HCS AMER Converged Infrastructure | P2: Douglas Lumb | Q2: Bethany Rana | R2: 14 | T2: Custom Model | U2: 13 | V2: Inactive | W2: 0 | Y2: 08:30-18:00 CST | Z2: Sat-Fri | AB2: English | AC2: #N/A
A3: CV03 | B3: HCS APJ Converged Infrastructure | C3: D'Arcy, Mark | D3: GNCS | E3: Powerflex | F3: Y | G3: Combined | H3: APJ | J3: 0.629 | K3: 0.022785399 | M3: 12/7 | N3: L1 | O3: =A3&"_"&B3 -> CV03_HCS APJ Converged Infrastructure | P3: Douglas Lumb | Q3: Bethany Rana | R3: 14 | T3: Custom Model | U3: 13 | V3: Inactive | W3: 0 | Y3: 06:00-21:00 IST | Z3: Sat-Fri | AB3: English | AC3: #N/A
A4: CV04 | B4: HCS EMEA Converged Infrastructure | C4: D'Arcy, Mark | D4: GNCS | E4: Powerflex | F4: Y | G4: Combined | H4: EMEA | J4: 0.617 | K4: 0.03896738 | M4: 12/7 | N4: L1 | O4: =A4&"_"&B4 -> CV04_HCS EMEA Converged Infrastructure | P4: Douglas Lumb | Q4: Bethany Rana | R4: 14 | T4: Custom Model | U4: 13 | V4: Inactive | W4: 0 | Y4: 01:00-09:00 CST | Z4: Sat- Fri | AB4: English | AC4: #N/A
A5: CV05 | B5: HCS Global Converged Infrastructure | C5: D'Arcy, Mark | D5: GNCS | E5: Powerflex | F5: Y | G5: Combined | H5: Global | J5: 0.633 | K5: 0.01867017 | M5: 24/7 | N5: Non-L1 | O5: =A5&"_"&B5 -> CV05_HCS Global Converged Infrastructure | P5: Douglas Lumb | Q5: Bethany Rana | R5: 24 | T5: Custom Model | U5: 13 | V5: Inactive | W5: 0 | Y5: 24*7 | Z5: Sat- Fri | AB5: English | AC5: #N/A
A6: BT02 | B6: Brazil Midrange | C6: Kenneally, Niall | D6: Midrange | E6: Midrange | F6: Y | G6: Front Line | H6: LATAM | I6: Brazil | J6: 0.626 | K6: 0.015604681 | M6: 0 | N6: L1 | O6: =A6&"_"&B6 -> BT02_Brazil Midrange | P6: Vikesh Gupta - Dellteam | Q6: Lucas Serafim | T6: Custom Model | U6: 13 | V6: Inactive | W6: 0 | Y6: #N/A | Z6: #N/A | AB6: Portuguese | AC6: #N/A
A7: BT03 | B7: MMCLA Midrange | C7: Kenneally, Niall | D7: Midrange | E7: Midrange | F7: Y | G7: Front Line | H7: LATAM | I7: MMCLA | J7: 0.626 | K7: 0.015604681 | M7: 0 | N7: L1 | O7: =A7&"_"&B7 -> BT03_MMCLA Midrange | P7: Vikesh Gupta - Dellteam | Q7: Lucas Serafim | T7: Custom Model | U7: 13 | V7: Inactive | W7: 0 | Y7: #N/A | Z7: #N/A | AB7: Spanish | AC7: #N/A
A8: HE02 | B8: Global AST | C8: Brown, Dexter | D8: GIST | E8: GIST | F8: N | G8: Backline | H8: EMEA | I8: Egypt | J8: 0.633 | M8: 12/7 | N8: L1 | O8: =A8&"_"&B8 -> HE02_Global AST | P8: Zhuo Chen | Q8: StephenRaj Kumar / CZ | R8: 14 | T8: Custom Model | U8: 13 | V8: Inactive | W8: 28 | Y8: Sat: 08:00-17:00, Sun-Fri 24/6 CST | Z8: Sat- Fri | AB8: English | AC8: Bansode, Mahendra - Dell Team
A9: BT10 | B9: CCC CNS Mandarin Voice | C9: Yap, Diane | D9: Server | E9: Server | F9: Y | G9: Front Line | H9: APJ | I9: China | J9: 0.629 | K9: 0.0078864353 | N9: L1 | O9: =A9&"_"&B9 -> BT10_CCC CNS Mandarin Voice | P9: Sarthak Shahir - Dellteam | Q9: StephenRaj Kumar | R9: 24 | T9: ESG | U9: 13 | V9: Inactive | W9: 59 | AA9: =IFERROR("Queue Got Merged in "&VLOOKUP(A9,'CQNs Merged_Split'!$B$7:$D$103,3,FALSE),"") | AB9: Mandarin | AC9: Wei Han, Ying - Dell Team
A10: CC14 | B10: CCC CNS Cantonese | C10: Yap, Diane | D10: Server | E10: Server | F10: Y | G10: Front Line | H10: APJ | I10: China | J10: 0.629 | K10: 0.022785399 | M10: 12/5 | N10: L1 | O10: =A10&"_"&B10 -> CC14_CCC CNS Cantonese | P10: Sarthak Shahir - Dellteam | Q10: StephenRaj Kumar | R10: 8 | T10: ESG | U10: 13 | V10: Inactive | W10: 11 | Y10: Email & Voice: 24*7, Chat: Mon-Fri 09:00-18:00 (GMT+8) | Z10: Sat- Fri | AA10: =IFERROR("Queue Got Merged in "&VLOOKUP(A10,'CQNs Merged_Split'!$B$7:$D$103,3,FALSE),"") | AB10: Cantonese | AC10: #N/A
A11: CE03 | B11: CCC CNS Mandarin Email | C11: Yap, Diane | D11: Server | E11: Server | F11: Y | G11: Front Line | H11: APJ | I11: China | J11: 0.629 | K11: 0.022785399 | M11: 12/5 | N11: L1 | O11: =A11&"_"&B11 -> CE03_CCC CNS Mandarin Email | P11: Sarthak Shahir - Dellteam | Q11: StephenRaj Kumar | R11: 8 | T11: ESG | U11: 13 | V11: Inactive | W11: 9 | Y11: Email: 24*7, Chat: Mon-Fri 8:30-17:30 (GMT+8) | Z11: Sat- Fri | AA11: =IFERROR("Queue Got Merged in "&VLOOKUP(A11,'CQNs Merged_Split'!$B$7:$D$103,3,FALSE),"") | AB11: Mandarin | AC11: #N/A
A12: AM02 | B12: Enterprise Support Services US | C12: No Assigned L6 | E12: Enterprise | F12: Y | G12: #N/A | H12: NAMER | I12: United States | J12: 0.648 | M12: 12/7 | O12: =A12&"_"&B12 -> AM02_Enterprise Support Services US | P12: Zhuo Chen | R12: 14 | T12: ESG | V12: Inactive | W12: 0 | Y12: #N/A | Z12: #N/A | AB12: English | AC12: #N/A
A13: AM04 | B13: Networking ProSupport Analysts US | C13: No Assigned L6 | D13: Networking | E13: Networking | F13: Y | G13: #N/A | H13: NAMER | I13: United States | J13: 0.648 | M13: 12/7 | O13: =A13&"_"&B13 -> AM04_Networking ProSupport Analysts US | P13: Zhuo Chen | R13: 14 | T13: ESG | V13: Inactive | W13: 0 | Y13: #N/A | Z13: #N/A | AB13: English | AC13: #N/A
A14: AM05 | B14: Networking ProSupport RTSE US | C14: No Assigned L6 | D14: Networking | E14: Networking | F14: Y | G14: #N/A | H14: NAMER | I14: United States | J14: 0.648 | M14: 12/7 | O14: =A14&"_"&B14 -> AM05_Networking ProSupport RTSE US | P14: Zhuo Chen | R14: 14 | T14: ESG | V14: Inactive | W14: 0 | Y14: #N/A | Z14: #N/A | AB14: English | AC14: #N/A
A15: AO06 | B15: APJ Upsell-Operations Multi | C15: No Assigned L6 | D15: All | E15: All | F15: Y | G15: #N/A | H15: APJ | I15: India | J15: 0.629 | M15: 12/7 | O15: =A15&"_"&B15 -> AO06_APJ Upsell-Operations Multi | P15: Zhuo Chen | R15: 14 | T15: ESG | V15: Inactive | W15: 0 | Y15: #N/A | Z15: #N/A | AB15: Multiple Languages | AC15: #N/A
A16: BR02 | B16: Brazil Senior and Master Engineer | C16: No Assigned L6 | D16: Server | E16: Enterprise | F16: N | G16: #N/A | H16: LATAM | I16: Brazil | J16: 0.571 | M16: 12/7 | O16: =A16&"_"&B16 -> BR02_Brazil Senior and Master Engineer | P16: Zhuo Chen | R16: 14 | T16: ESG | V16: Inactive | W16: 0 | Y16: #N/A | Z16: #N/A | AB16: Portuguese | AC16: #N/A
A17: CC07 | B17: Enterprise Core CCC | C17: No Assigned L6 | D17: Server | E17: Server | F17: Y | G17: #N/A | H17: APJ | I17: China | J17: 0.629 | M17: 12/7 | O17: =A17&"_"&B17 -> CC07_Enterprise Core CCC | P17: Zhuo Chen | R17: 14 | T17: ESG | V17: Inactive | W17: 0 | Y17: #N/A | Z17: #N/A | AB17: Mandarin | AC17: #N/A
A18: CC09 | B18: Server ProSupport CCC | C18: No Assigned L6 | F18: Y | G18: #N/A | O18: =A18&"_"&B18 -> CC09_Server ProSupport CCC | P18: Zhuo Chen | T18: ESG | V18: Inactive | W18: 0 | Y18: #N/A | Z18: #N/A | AB18: Mandarin | AC18: #N/A
A19: CC22 | B19: Enterprise TW | C19: No Assigned L6 | F19: Y | G19: #N/A | O19: =A19&"_"&B19 -> CC22_Enterprise TW | P19: Zhuo Chen | T19: ESG | V19: Inactive | W19: 0 | Y19: #N/A | Z19: #N/A | AB19: Mandarin | AC19: #N/A
A20: CC23 | B20: Server ProSupport Plus CCC | C20: No Assigned L6 | F20: Y | G20: #N/A | O20: =A20&"_"&B20 -> CC23_Server ProSupport Plus CCC | P20: Zhuo Chen | T20: ESG | V20: Inactive | W20: 0 | Y20: #N/A | Z20: #N/A | AB20: Mandarin | AC20: #N/A
A21: CE01 | B21: Enterprise Echannel CCC | C21: No Assigned L6 | E21: Server | F21: Y | G21: #N/A | H21: APJ | I21: China | J21: 0.629 | M21: 12/7 | O21: =A21&"_"&B21 -> CE01_Enterprise Echannel CCC | P21: Zhuo Chen | R21: 14 | T21: ESG | V21: Inactive | W21: 0 | Y21: #N/A | Z21: #N/A | AB21: Mandarin | AC21: #N/A
A22: CG Comp | C22: No Assigned L6 | F22: Y | G22: #N/A | O22: =A22&"_"&B22 -> CG Comp_ | P22: #N/A | T22: ESG | V22: Inactive | W22: 0 | Y22: #N/A | Z22: #N/A | AB22: #N/A | AC22: #N/A
A23: CT16 | B23: CTE KOR | C23: No Assigned L6 | D23: CTE | E23: CTE | F23: Y | G23: #N/A | H23: Global | I23: Global | J23: 0.633 | M23: 12/7 | N23: CTE | O23: =A23&"_"&B23 -> CT16_CTE KOR | P23: Zhuo Chen | R23: 14 | T23: ESG | V23: Inactive | W23: 0 | Y23: #N/A | Z23: #N/A | AB23: Korean | AC23: #N/A
A24: CT36 | B24: Networking SPSPE | C24: No Assigned L6 | F24: Y | G24: #N/A | O24: =A24&"_"&B24 -> CT36_Networking SPSPE | P24: Zhuo Chen | T24: ESG | V24: Inactive | W24: 0 | Y24: #N/A | Z24: #N/A | AB24: English | AC24: #N/A
A25: DE12 | B25: GER Solutions (HAL) | C25: No Assigned L6 | D25: Server | E25: Server | F25: Y | G25: #N/A | H25: EMEA | I25: Germany | J25: 0.617 | M25: 12/7 | O25: =A25&"_"&B25 -> DE12_GER Solutions (HAL) | P25: Zhuo Chen | R25: 14 | T25: ESG | V25: Inactive | W25: 0 | Y25: #N/A | Z25: #N/A | AB25: German | AC25: #N/A
A26: FD01 | B26: Federal Support NA | C26: No Assigned L6 | E26: Enterprise | F26: Y | G26: #N/A | H26: NAMER | I26: United States | J26: 0.648 | M26: 12/7 | O26: =A26&"_"&B26 -> FD01_Federal Support NA | P26: Zhuo Chen | R26: 14 | T26: ESG | V26: Inactive | W26: 0 | Y26: #N/A | Z26: #N/A | AB26: English | AC26: #N/A
A27: FED4 | B27: Federal Server US | C27: No Assigned L6 | D27: Server | E27: Server | F27: Y | G27: #N/A | H27: NAMER | I27: United States | J27: 0.648 | M27: 12/5 | N27: L1 | O27: =A27&"_"&B27 -> FED4_Federal Server US | P27: Prachi Gupta - Dellteam | R27: 8 | T27: ESG | V27: Inactive | W27: 0 | Y27: #N/A | Z27: #N/A | AB27: English | AC27: #N/A
A28: FED6 | B28: US Federal Support Storage | C28: No Assigned L6 | D28: Storage | E28: Storage | F28: Y | G28: #N/A | H28: NAMER | I28: United States | J28: 0.648 | M28: 12/5 | O28: =A28&"_"&B28 -> FED6_US Federal Support Storage | P28: Zhuo Chen | R28: 8 | T28: ESG | V28: Inactive | W28: 0 | Y28: #N/A | Z28: #N/A | AB28: English | AC28: #N/A
A29: FR08 | B29: FRA Solutions (MTP) | C29: No Assigned L6 | D29: Server | E29: Server | F29: Y | G29: #N/A | H29: EMEA | I29: France | J29: 0.617 | M29: 12/7 | O29: =A29&"_"&B29 -> FR08_FRA Solutions (MTP) | P29: Zhuo Chen | R29: 14 | T29: ESG | V29: Inactive | W29: 0 | Y29: #N/A | Z29: #N/A | AB29: French | AC29: #N/A
A30: FR12 | B30: FRA ProSupp Server Alternate | C30: No Assigned L6 | D30: Server | E30: Server | F30: Y | G30: #N/A | H30: EMEA | I30: SER | J30: 0.617 | M30: 10/5 | N30: L1 | O30: =A30&"_"&B30 -> FR12_FRA ProSupp Server Alternate | P30: Vikesh Gupta - Dellteam | R30: 7 | T30: ESG | V30: Inactive | W30: 0 | Y30: #N/A | Z30: #N/A | AB30: French | AC30: #N/A
A31: FR13 | B31: ProSupp EQL (MTP) | C31: No Assigned L6 | D31: Storage | E31: Storage | F31: Y | G31: #N/A | H31: EMEA | I31: #N/A | J31: 0.617 | M31: 10/5 | O31: =A31&"_"&B31 -> FR13_ProSupp EQL (MTP) | P31: Zhuo Chen | R31: 7 | T31: ESG | V31: Inactive | W31: 0 | Y31: #N/A | Z31: #N/A | AB31: Multiple Languages | AC31: #N/A
A32: FR23 | B32: FRA ProSupp Storage (MTP) | C32: No Assigned L6 | D32: Storage | E32: Storage | F32: Y | G32: #N/A | H32: EMEA | I32: France | J32: 0.617 | M32: 12/7 | O32: =A32&"_"&B32 -> FR23_FRA ProSupp Storage (MTP) | P32: Zhuo Chen | R32: 14 | T32: ESG | V32: Inactive | W32: 0 | Y32: #N/A | Z32: #N/A | AB32: French | AC32: #N/A
A33: GB08 | B33: UKISA Basic Enterprise (BGL) | C33: No Assigned L6 | D33: Server | E33: Server | F33: Y | G33: #N/A | H33: EMEA | I33: United Kingdom | J33: 0.617 | M33: 14/5 | O33: =A33&"_"&B33 -> GB08_UKISA Basic Enterprise (BGL) | P33: Zhuo Chen | R33: 10 | T33: ESG | V33: Inactive | W33: 0 | Y33: #N/A | Z33: #N/A | AB33: English | AC33: #N/A
A34: GB09 | B34: ProSupp Storage Co Pilot (CWD) | C34: No Assigned L6 | D34: Storage | E34: Storage | F34: Y | G34: #N/A | H34: EMEA | I34: United Kingdom | J34: 0.617 | M34: 12/7 | O34: =A34&"_"&B34 -> GB09_ProSupp Storage Co Pilot (CWD) | P34: Zhuo Chen | R34: 14 | T34: ESG | V34: Inactive | W34: 0 | Y34: #N/A | Z34: #N/A | AB34: Multiple Languages | AC34: #N/A
A35: GB10 | B35: ProSupp EQL (CWD) | C35: No Assigned L6 | D35: Storage | E35: Storage | F35: Y | G35: #N/A | H35: EMEA | I35: #N/A | J35: 0.617 | M35: 10/5 | O35: =A35&"_"&B35 -> GB10_ProSupp EQL (CWD) | P35: Zhuo Chen | R35: 7 | T35: ESG | V35: Inactive | W35: 0 | Y35: #N/A | Z35: #N/A | AB35: Multiple Languages | AC35: #N/A
A36: GB14 | B36: ENG Solutions (CWD) | C36: No Assigned L6 | D36: Server | E36: Server | F36: Y | G36: #N/A | H36: EMEA | I36: United Kingdom | J36: 0.617 | M36: 12/7 | O36: =A36&"_"&B36 -> GB14_ENG Solutions (CWD) | P36: Zhuo Chen | R36: 14 | T36: ESG | V36: Inactive | W36: 0 | Y36: #N/A | Z36: #N/A | AB36: English | AC36: #N/A
A37: GB29 | B37: EMEA ProSupport Powerstore | C37: No Assigned L6 | D37: Storage | E37: Storage | F37: Y | G37: #N/A | H37: EMEA | I37: SER | J37: 0.617 | M37: 11/5 | N37: L1 | O37: =A37&"_"&B37 -> GB29_EMEA ProSupport Powerstore | P37: Vikesh Gupta - Dellteam | R37: 8 | T37: ESG | V37: Inactive | W37: 0 | Y37: #N/A | Z37: #N/A | AB37: Multiple Languages | AC37: #N/A
A38: GG01 | B38: GER ProSupp Storage Co Pilot | C38: No Assigned L6 | D38: Storage | E38: Storage | F38: Y | G38: #N/A | H38: EMEA | I38: Germany | J38: 0.617 | M38: 12/7 | O38: =A38&"_"&B38 -> GG01_GER ProSupp Storage Co Pilot | P38: Zhuo Chen | R38: 14 | T38: ESG | V38: Inactive | W38: 0 | Y38: #N/A | Z38: #N/A | AB38: German | AC38: #N/A
A39: HE17 | B39: HES Global Operations | C39: Yap, Diane | D39: Social | E39: High End Storage | F39: N | G39: #N/A | H39: Global | I39: Global | J39: 0.633 | M39: 12/7 | O39: =A39&"_"&B39 -> HE17_HES Global Operations | P39: Zhuo Chen | R39: 14 | T39: ESG | V39: Inactive | W39: 0.66666667 | Y39: #N/A | Z39: #N/A | AB39: English | AC39: #N/A
A40: HWPA | B40: Honeywell Panama | C40: No Assigned L6 | F40: Y | G40: #N/A | O40: =A40&"_"&B40 -> HWPA_Honeywell Panama | P40: Zhuo Chen | T40: ESG | V40: Inactive | W40: 0 | Y40: #N/A | Z40: #N/A | AB40: English/Spanish | AC40: #N/A
...

Sheet Sheet7
A1: CCOQueueAbbr | B1: CCOQueueCode | C1: 202641 | D1: 202642 | E1: 202643 | F1: 202644 | G1: 202645
A2: AP10 | B2: APJ UDS PowerScale Chinese | C2: 18 | D2: 18 | E2: 18 | F2: 18 | G2: 18 | H2: =VLOOKUP(A2,UniqueCCOQueueCodes!$A$1:$T$607,6,0) -> Y | I2: =VLOOKUP(A2,UniqueCCOQueueCodes!$A$1:$T$607,20,0) -> HES
A3: AP11 | B3: APJ UDS PowerScale Japanese | C3: 13 | D3: 13 | E3: 13 | F3: 13 | G3: 13 | H3: =VLOOKUP(A3,UniqueCCOQueueCodes!$A$1:$T$607,6,0) -> Y | I3: =VLOOKUP(A3,UniqueCCOQueueCodes!$A$1:$T$607,20,0) -> HES
A4: AP12 | B4: APJ DPD AVAMAR Chinese | C4: 10 | D4: 9 | E4: 9 | F4: 9 | G4: 9 | H4: =VLOOKUP(A4,UniqueCCOQueueCodes!$A$1:$T$607,6,0) -> Y | I4: =VLOOKUP(A4,UniqueCCOQueueCodes!$A$1:$T$607,20,0) -> HES
A5: AP13 | B5: APJ HES Connectivity Chinese | C5: 7 | D5: 7 | E5: 7 | F5: 7 | G5: 7 | H5: =VLOOKUP(A5,UniqueCCOQueueCodes!$A$1:$T$607,6,0) -> Y | I5: =VLOOKUP(A5,UniqueCCOQueueCodes!$A$1:$T$607,20,0) -> HES
A6: AP14 | B6: APJ DPD DataDomain Chinese | C6: 12 | D6: 12 | E6: 12 | F6: 12 | G6: 11 | H6: =VLOOKUP(A6,UniqueCCOQueueCodes!$A$1:$T$607,6,0) -> Y | I6: =VLOOKUP(A6,UniqueCCOQueueCodes!$A$1:$T$607,20,0) -> HES
A7: AP15 | B7: HCS APJ VxRail Chinese | C7: 25 | D7: 25 | E7: 25 | F7: 24 | G7: 23 | H7: =VLOOKUP(A7,UniqueCCOQueueCodes!$A$1:$T$607,6,0) -> Y | I7: =VLOOKUP(A7,UniqueCCOQueueCodes!$A$1:$T$607,20,0) -> HES
A8: AP16 | B8: HCS APJ VxRail Japanese | C8: 16 | D8: 16 | E8: 16 | F8: 16 | G8: 16 | H8: =VLOOKUP(A8,UniqueCCOQueueCodes!$A$1:$T$607,6,0) -> Y | I8: =VLOOKUP(A8,UniqueCCOQueueCodes!$A$1:$T$607,20,0) -> HES
A9: AP17 | B9: APJ HES Integrated_Software Chinese | C9: 6 | D9: 6 | E9: 6 | F9: 6 | G9: 6 | H9: =VLOOKUP(A9,UniqueCCOQueueCodes!$A$1:$T$607,6,0) -> Y | I9: =VLOOKUP(A9,UniqueCCOQueueCodes!$A$1:$T$607,20,0) -> HES
A10: AP18 | B10: APJ DPD Networker Chinese | C10: 16 | D10: 16 | E10: 16 | F10: 16 | G10: 15 | H10: =VLOOKUP(A10,UniqueCCOQueueCodes!$A$1:$T$607,6,0) -> Y | I10: =VLOOKUP(A10,UniqueCCOQueueCodes!$A$1:$T$607,20,0) -> HES
A11: AP19 | B11: APJ HES Symmetrix Chinese | C11: 10 | D11: 10 | E11: 10 | F11: 10 | G11: 10 | H11: =VLOOKUP(A11,UniqueCCOQueueCodes!$A$1:$T$607,6,0) -> Y | I11: =VLOOKUP(A11,UniqueCCOQueueCodes!$A$1:$T$607,20,0) -> HES
A12: AP20 | B12: APJ HES Symmetrix Japanese | C12: 10 | D12: 10 | E12: 10 | F12: 10 | G12: 10 | H12: =VLOOKUP(A12,UniqueCCOQueueCodes!$A$1:$T$607,6,0) -> Y | I12: =VLOOKUP(A12,UniqueCCOQueueCodes!$A$1:$T$607,20,0) -> HES
A13: AP21 | B13: APJ HES SymmSW Chinese | C13: 2 | D13: 2 | E13: 2 | F13: 2 | G13: 2 | H13: =VLOOKUP(A13,UniqueCCOQueueCodes!$A$1:$T$607,6,0) -> Y | I13: =VLOOKUP(A13,UniqueCCOQueueCodes!$A$1:$T$607,20,0) -> HES
... A33: BZ24 | B33: LATAM Compute Portuguese | C33: 26 | D33: 26 | E33: 26 | F33: 26 | G33: 27 | H33: =VLOOKUP(A33,UniqueCCOQueueCodes!$A$1:$T$607,6,0) -> Y | I33: =VLOOKUP(A33,UniqueCCOQueueCodes!$A$1:$T$607,20,0) -> ESG
A34: CC12 | B34: Social Media CCC | C34: 1 | D34: 1 | E34: 1 | F34: 1 | H34: =VLOOKUP(A34,UniqueCCOQueueCodes!$A$1:$T$607,6,0) -> Y | I34: =VLOOKUP(A34,UniqueCCOQueueCodes!$A$1:$T$607,20,0) -> Not Planned
A35: CC14 | B35: CCC CNS Cantonese | C35: 12 | D35: 12 | E35: 12 | F35: 12 | H35: =VLOOKUP(A35,UniqueCCOQueueCodes!$A$1:$T$607,6,0) -> Y | I35: =VLOOKUP(A35,UniqueCCOQueueCodes!$A$1:$T$607,20,0) -> ESG
A36: CE03 | B36: CCC CNS Mandarin Email | C36: 8 | D36: 8 | E36: 8 | F36: 8 | H36: =VLOOKUP(A36,UniqueCCOQueueCodes!$A$1:$T$607,6,0) -> Y | I36: =VLOOKUP(A36,UniqueCCOQueueCodes!$A$1:$T$607,20,0) -> ESG
A37: CNS Technical Lead | B37: CNS Technical Lead | C37: 9 | D37: 9 | E37: 9 | F37: 9 | G37: 9 | H37: =VLOOKUP(A37,UniqueCCOQueueCodes!$A$1:$T$607,6,0) -> #N/A | I37: =VLOOKUP(A37,UniqueCCOQueueCodes!$A$1:$T$607,20,0) -> #N/A
A38: CST5 | B38: CST VIC | C38: 0 | D38: 0 | E38: 0 | F38: 0 | G38: 0 | H38: =VLOOKUP(A38,UniqueCCOQueueCodes!$A$1:$T$607,6,0) -> N | I38: =VLOOKUP(A38,UniqueCCOQueueCodes!$A$1:$T$607,20,0) -> Not Planned
A39: CT20 | B39: GLOBAL E2E Connectivity | C39: 32 | D39: 31 | E39: 31 | F39: 31 | G39: 31 | H39: =VLOOKUP(A39,UniqueCCOQueueCodes!$A$1:$T$607,6,0) -> Y | I39: =VLOOKUP(A39,UniqueCCOQueueCodes!$A$1:$T$607,20,0) -> Custom Model
A40: CT23 | B40: GLOBAL HES BSAFE | C40: 2 | D40: 2 | E40: 2 | F40: 2 | G40: 2 | H40: =VLOOKUP(A40,UniqueCCOQueueCodes!$A$1:$T$607,6,0) -> Y | I40: =VLOOKUP(A40,UniqueCCOQueueCodes!$A$1:$T$607,20,0) -> Not Planned
A41: CT24 | B41: HCS Global DSE | C41: 134.8134 | D41: 134.8134 | E41: 134.8134 | F41: 134.8134 | G41: 134.8134 | H41: =VLOOKUP(A41,UniqueCCOQueueCodes!$A$1:$T$607,6,0) -> N | I41: =VLOOKUP(A41,UniqueCCOQueueCodes!$A$1:$T$607,20,0) -> Not Planned
A42: CT25 | B42: Global Compute Hardware | C42: 102 | D42: 101 | E42: 101 | F42: 100 | G42: 91 | H42: =VLOOKUP(A42,UniqueCCOQueueCodes!$A$1:$T$607,6,0) -> Y | I42: =VLOOKUP(A42,UniqueCCOQueueCodes!$A$1:$T$607,20,0) -> HES
A43: CT26 | B43: Global ESG Midrange Backline | C43: 108.8 | D43: 108.8 | E43: 108.8 | F43: 108.8 | G43: 107.8 | H43: =VLOOKUP(A43,UniqueCCOQueueCodes!$A$1:$T$607,6,0) -> Y | I43: =VLOOKUP(A43,UniqueCCOQueueCodes!$A$1:$T$607,20,0) -> HES
A44: CT30 | B44: Global Networking | C44: 68 | D44: 68 | E44: 68 | F44: 68 | G44: 65 | H44: =VLOOKUP(A44,UniqueCCOQueueCodes!$A$1:$T$607,6,0) -> Y | I44: =VLOOKUP(A44,UniqueCCOQueueCodes!$A$1:$T$607,20,0) -> HES
A45: CT37 | B45: APJ HES CST Japanese | C45: 10 | D45: 10 | E45: 10 | F45: 10 | G45: 10 | H45: =VLOOKUP(A45,UniqueCCOQueueCodes!$A$1:$T$607,6,0) -> Y | I45: =VLOOKUP(A45,UniqueCCOQueueCodes!$A$1:$T$607,20,0) -> Custom Model
A46: CT67 | B46: RPS Remote Proactive Services | C46: 182 | D46: 182 | E46: 182 | F46: 181 | G46: 181 | H46: =VLOOKUP(A46,UniqueCCOQueueCodes!$A$1:$T$607,6,0) -> Y | I46: =VLOOKUP(A46,UniqueCCOQueueCodes!$A$1:$T$607,20,0) -> HES
A47: CT68 | B47: RPS Proactive Systems Maintenance | C47: 41 | D47: 41 | E47: 41 | F47: 41 | G47: 41 | H47: =VLOOKUP(A47,UniqueCCOQueueCodes!$A$1:$T$607,6,0) -> N | I47: =VLOOKUP(A47,UniqueCCOQueueCodes!$A$1:$T$607,20,0) -> Not Planned
A48: CZ03 | B48: CZE Enterprise (BRA) | C48: 10 | D48: 10 | E48: 10 | F48: 9 | G48: 9 | H48: =VLOOKUP(A48,UniqueCCOQueueCodes!$A$1:$T$607,6,0) -> Y | I48: =VLOOKUP(A48,UniqueCCOQueueCodes!$A$1:$T$607,20,0) -> ESG
... A145: NF22 | B145: HES Manager | C145: 2 | D145: 2 | E145: 2 | F145: 2 | G145: 2 | H145: =VLOOKUP(A145,UniqueCCOQueueCodes!$A$1:$T$607,6,0) -> N | I145: =VLOOKUP(A145,UniqueCCOQueueCodes!$A$1:$T$607,20,0) -> Not Planned
A146: NF23 | B146: HES Non-Frontline | C146: 1 | D146: 1 | E146: 1 | F146: 1 | H146: =VLOOKUP(A146,UniqueCCOQueueCodes!$A$1:$T$607,6,0) -> N | I146: =VLOOKUP(A146,UniqueCCOQueueCodes!$A$1:$T$607,20,0) -> Not Planned
A147: NF25 | B147: HES Quality Coach | C147: 16 | D147: 16 | E147: 16 | F147: 16 | G147: 16 | H147: =VLOOKUP(A147,UniqueCCOQueueCodes!$A$1:$T$607,6,0) -> N | I147: =VLOOKUP(A147,UniqueCCOQueueCodes!$A$1:$T$607,20,0) -> Not Planned
A148: NF26 | B148: HES Technical Lead | C148: 5 | D148: 5 | E148: 5 | F148: 5 | G148: 5 | H148: =VLOOKUP(A148,UniqueCCOQueueCodes!$A$1:$T$607,6,0) -> N | I148: =VLOOKUP(A148,UniqueCCOQueueCodes!$A$1:$T$607,20,0) -> Not Planned
A149: NF28 | B149: LATAM Non-Frontline | C149: 1 | D149: 1 | E149: 1 | F149: 1 | G149: 1 | H149: =VLOOKUP(A149,UniqueCCOQueueCodes!$A$1:$T$607,6,0) -> N | I149: =VLOOKUP(A149,UniqueCCOQueueCodes!$A$1:$T$607,20,0) -> Not Planned
A150: NF30 | B150: LATAM Quality Coach | C150: 11 | D150: 11 | E150: 11 | F150: 11 | G150: 11 | H150: =VLOOKUP(A150,UniqueCCOQueueCodes!$A$1:$T$607,6,0) -> N | I150: =VLOOKUP(A150,UniqueCCOQueueCodes!$A$1:$T$607,20,0) -> Not Planned
A151: NF34 | B151: NAMER Quality Coach | C151: 25 | D151: 25 | E151: 25 | F151: 25 | G151: 25 | H151: =VLOOKUP(A151,UniqueCCOQueueCodes!$A$1:$T$607,6,0) -> N | I151: =VLOOKUP(A151,UniqueCCOQueueCodes!$A$1:$T$607,20,0) -> Not Planned
A152: NF37 | B152: Service Engineering Non-Frontline | C152: 1 | D152: 1 | E152: 1 | F152: 1 | G152: 1 | H152: =VLOOKUP(A152,UniqueCCOQueueCodes!$A$1:$T$607,6,0) -> N | I152: =VLOOKUP(A152,UniqueCCOQueueCodes!$A$1:$T$607,20,0) -> Not Planned
A153: NF42 | B153: SSO Non-Frontline | C153: 7 | D153: 7 | E153: 7 | F153: 7 | G153: 7 | H153: =VLOOKUP(A153,UniqueCCOQueueCodes!$A$1:$T$607,6,0) -> N | I153: =VLOOKUP(A153,UniqueCCOQueueCodes!$A$1:$T$607,20,0) -> Not Planned
A154: NF43 | B154: SSO NR-FLS | C154: 42 | D154: 42 | E154: 42 | F154: 42 | G154: 42 | H154: =VLOOKUP(A154,UniqueCCOQueueCodes!$A$1:$T$607,6,0) -> N | I154: =VLOOKUP(A154,UniqueCCOQueueCodes!$A$1:$T$607,20,0) -> Not Planned
A155: NF56 | B155: HCS Quality Coach | C155: 11 | D155: 11 | E155: 11 | F155: 11 | G155: 11 | H155: =VLOOKUP(A155,UniqueCCOQueueCodes!$A$1:$T$607,6,0) -> N | I155: =VLOOKUP(A155,UniqueCCOQueueCodes!$A$1:$T$607,20,0) -> Not Planned
...

Sheet Unique_CCO_Queue_Code_Update
A1: Queues AA Plan For | B1: epicenter_cco_queue_code | C1: epicenter_cco_queue_desc | D1: L5 | E1: Domain | F1: LOB Alignment | G1: Flag | H1: Resource Region | I1: Resource Sub Region | J1: Utilization | K1: Queue Description | L1: Capacity Planner | M1: Business Owner | N1: Coverage HC | O1: HES/ESG | P1: Status | Q1: Comment
A2: 1. Filter Out | B2: BT02 | C2: Brazil Midrange | D2: Kenneally, Niall | E2: Midrange | F2: Midrange | G2: Y | H2: LATAM | I2: Brazil | J2: 0.626 | K2: =B2&"_"&C2 -> BT02_Brazil Midrange | M2: Lucas Serafim | O2: Custom Model | P2: Inactive
A3: 1. Filter Out | B3: BT03 | C3: MMCLA Midrange | D3: Kenneally, Niall | E3: Midrange | F3: Midrange | G3: Y | H3: LATAM | I3: MMCLA | J3: 0.626 | K3: =B3&"_"&C3 -> BT03_MMCLA Midrange | M3: Lucas Serafim | O3: Custom Model | P3: Inactive
A4: 1. Filter Out | B4: CV02 | C4: HCS AMER Converged Infrastructure | D4: D'Arcy, Mark | E4: GNCS | F4: Powerflex | G4: Y | H4: NAMER | J4: 0.648 | K4: =B4&"_"&C4 -> CV02_HCS AMER Converged Infrastructure | M4: Bethany Rana | N4: 14 | O4: Custom Model | P4: Inactive
A5: 1. Filter Out | B5: CV03 | C5: HCS APJ Converged Infrastructure | D5: D'Arcy, Mark | E5: GNCS | F5: Powerflex | G5: Y | H5: APJ | J5: 0.629 | K5: =B5&"_"&C5 -> CV03_HCS APJ Converged Infrastructure | M5: Bethany Rana | N5: 14 | O5: Custom Model | P5: Inactive
A6: 1. Filter Out | B6: CV04 | C6: HCS EMEA Converged Infrastructure | D6: D'Arcy, Mark | E6: GNCS | F6: Powerflex | G6: Y | H6: EMEA | J6: 0.617 | K6: =B6&"_"&C6 -> CV04_HCS EMEA Converged Infrastructure | M6: Bethany Rana | N6: 14 | O6: Custom Model | P6: Inactive
A7: 1. Filter Out | B7: CV05 | C7: HCS Global Converged Infrastructure | D7: D'Arcy, Mark | E7: GNCS | F7: Powerflex | G7: Y | H7: Global | J7: 0.633 | K7: =B7&"_"&C7 -> CV05_HCS Global Converged Infrastructure | M7: Bethany Rana | N7: 24 | O7: Custom Model | P7: Inactive
A8: 1. Filter Out | B8: HE02 | C8: Global AST | D8: Brown, Dexter | E8: GIST | F8: GIST | G8: N | H8: EMEA | I8: Egypt | J8: 0.633 | K8: =B8&"_"&C8 -> HE02_Global AST | M8: StephenRaj Kumar / CZ | N8: 14 | O8: Custom Model | P8: Inactive
A9: 1. Filter Out | B9: AM02 | C9: Enterprise Support Services US | D9: No Assigned L6 | F9: Enterprise | G9: Y | H9: NAMER | I9: United States | J9: 0.648 | K9: =B9&"_"&C9 -> AM02_Enterprise Support Services US | N9: 14 | O9: ESG | P9: Inactive
A10: 1. Filter Out | B10: AM04 | C10: Networking ProSupport Analysts US | D10: No Assigned L6 | E10: Networking | F10: Networking | G10: Y | H10: NAMER | I10: United States | J10: 0.648 | K10: =B10&"_"&C10 -> AM04_Networking ProSupport Analysts US | N10: 14 | O10: ESG | P10: Inactive
A11: 1. Filter Out | B11: AM05 | C11: Networking ProSupport RTSE US | D11: No Assigned L6 | E11: Networking | F11: Networking | G11: Y | H11: NAMER | I11: United States | J11: 0.648 | K11: =B11&"_"&C11 -> AM05_Networking ProSupport RTSE US | N11: 14 | O11: ESG | P11: Inactive
A12: 1. Filter Out | B12: AO06 | C12: APJ Upsell-Operations Multi | D12: No Assigned L6 | E12: All | F12: All | G12: Y | H12: APJ | I12: India | J12: 0.629 | K12: =B12&"_"&C12 -> AO06_APJ Upsell-Operations Multi | N12: 14 | O12: ESG | P12: Inactive
A13: 1. Filter Out | B13: AZ09 | C13: Networking ProSupport ANZ | D13: Yap, Diane | E13: Networking | F13: Networking | G13: Y | H13: APJ | I13: Australia | J13: 0.629 | K13: =B13&"_"&C13 -> AZ09_Networking ProSupport ANZ | M13: Chen Zhou | N13: 8 | O13: ESG | P13: Inactive
A14: 1. Filter Out | B14: BPS1 | C14: Brazil Powerstore | D14: No Assigned L6 | E14: Storage | F14: Storage | G14: Y | H14: LATAM | I14: Brazil | J14: 0.571 | K14: =B14&"_"&C14 -> BPS1_Brazil Powerstore | M14: Darrick Nelsen | N14: 8 | O14: ESG | P14: Inactive
A15: 1. Filter Out | B15: BR02 | C15: Brazil Senior and Master Engineer | D15: No Assigned L6 | E15: Server | F15: Enterprise | G15: Y | H15: LATAM | I15: Brazil | J15: 0.571 | K15: =B15&"_"&C15 -> BR02_Brazil Senior and Master Engineer | N15: 14 | O15: ESG | P15: Inactive
A16: 1. Filter Out | B16: BW01 | C16: CCC Compute ProSupport Mandarin Voice BW | D16: Yap, Diane | E16: Server | F16: Server | G16: Y | H16: APJ | I16: China | J16: 0.629 | K16: =B16&"_"&C16 -> BW01_CCC Compute ProSupport Mandarin Voice BW | M16: Chen Zhou | N16: 14 | O16: ESG | P16: Inactive
A17: 1. Filter Out | B17: BZ10 | C17: BRZ HC Server Voice (EL) | D17: No Assigned L6 | E17: Server | F17: Server | G17: Y | H17: LATAM | I17: Brazil | J17: 0.571 | K17: =B17&"_"&C17 -> BZ10_BRZ HC Server Voice (EL) | M17: Darrick Nelsen | N17: 8 | O17: ESG | P17: Inactive
A18: 1. Filter Out | B18: BZ11 | C18: BRZ HC Storage Voice (EL) | D18: No Assigned L6 | E18: Storage | F18: Storage | G18: Y | H18: LATAM | I18: Brazil | J18: 0.571 | K18: =B18&"_"&C18 -> BZ11_BRZ HC Storage Voice (EL) | M18: Darrick Nelsen | N18: 8 | O18: ESG | P18: Inactive
A19: 1. Filter Out | B19: BZ13 | C19: BRZ LC Server Voice (EL) | D19: No Assigned L6 | E19: Server | F19: Server | G19: Y | H19: LATAM | I19: Brazil | J19: 0.571 | K19: =B19&"_"&C19 -> BZ13_BRZ LC Server Voice (EL) | M19: Darrick Nelsen | N19: 8 | O19: ESG | P19: Inactive
A20: 1. Filter Out | B20: BZ14 | C20: BRZ LC Storage Voice (EL) | D20: Kenneally, Niall | E20: Storage | F20: Storage | G20: Y | H20: LATAM | I20: Brazil | J20: 0.571 | K20: =B20&"_"&C20 -> BZ14_BRZ LC Storage Voice (EL) | M20: Lucas Serafim | N20: 8 | O20: ESG | P20: Inactive
A21: 1. Filter Out | B21: CC04 | C21: CCC Enterprise CMG Mandarin Voice BW | D21: Christmas, James | E21: Server | F21: Server | G21: Y | H21: APJ | I21: China | J21: 0.629 | K21: =B21&"_"&C21 -> CC04_CCC Enterprise CMG Mandarin Voice BW | N21: 14 | O21: ESG | P21: Inactive
A22: 1. Filter Out | B22: CC05 | C22: Networking CCC | D22: No Assigned L6 | E22: Networking | F22: Networking | G22: Y | H22: APJ | I22: China | J22: 0.629 | K22: =B22&"_"&C22 -> CC05_Networking CCC | M22: Chen Zhou | N22: 8 | O22: ESG | P22: Inactive
A23: 1. Filter Out | B23: CC07 | C23: Enterprise Core CCC | D23: No Assigned L6 | E23: Server | F23: Server | G23: Y | H23: APJ | I23: China | J23: 0.629 | K23: =B23&"_"&C23 -> CC07_Enterprise Core CCC | N23: 14 | O23: ESG | P23: Inactive
A24: 1. Filter Out | B24: CC09 | C24: Server ProSupport CCC | D24: No Assigned L6 | G24: Y | K24: =B24&"_"&C24 -> CC09_Server ProSupport CCC | O24: ESG | P24: Inactive
A25: 1. Filter Out | B25: CC10 | C25: Storage ProSupport CCC | D25: No Assigned L6 | E25: Storage | F25: Storage | G25: Y | H25: APJ | I25: China | J25: 0.629 | K25: =B25&"_"&C25 -> CC10_Storage ProSupport CCC | M25: Chen Zhou | N25: 8 | O25: ESG | P25: Inactive
A26: 1. Filter Out | B26: CC22 | C26: Enterprise TW | D26: No Assigned L6 | G26: Y | K26: =B26&"_"&C26 -> CC22_Enterprise TW | O26: ESG | P26: Inactive
A27: 1. Filter Out | B27: CC23 | C27: Server ProSupport Plus CCC | D27: No Assigned L6 | G27: Y | K27: =B27&"_"&C27 -> CC23_Server ProSupport Plus CCC | O27: ESG | P27: Inactive
A28: 1. Filter Out | B28: CC27 | C28: Server Combined CCC | D28: No Assigned L6 | E28: Server | F28: Server | G28: Y | H28: APJ | I28: China | J28: 0.629 | K28: =B28&"_"&C28 -> CC27_Server Combined CCC | M28: Chen Zhou | N28: 8 | O28: ESG | P28: Inactive
A29: 1. Filter Out | B29: CC28 | C29: APJ ESG Call Directors Chinese | D29: Yap, Diane | E29: CST | F29: Enterprise | G29: N | H29: APJ | I29: China | J29: 0.629 | K29: =B29&"_"&C29 -> CC28_APJ ESG Call Directors Chinese | M29: Chen Zhou | N29: 14 | O29: ESG | P29: Inactive
A30: 1. Filter Out | B30: CCB1 | C30: CCC Compute Basic Mandarin Voice BW | D30: Yap, Diane | E30: Server | F30: Server | G30: Y | H30: APJ | I30: China | J30: 0.629 | K30: =B30&"_"&C30 -> CCB1_CCC Compute Basic Mandarin Voice BW | M30: Chen Zhou | N30: 14 | O30: ESG | P30: Inactive
A31: 1. Filter Out | B31: CE01 | C31: Enterprise Echannel CCC | D31: No Assigned L6 | F31: Server | G31: Y | H31: APJ | I31: China | J31: 0.629 | K31: =B31&"_"&C31 -> CE01_Enterprise Echannel CCC | N31: 14 | O31: ESG | P31: Inactive
A32: 1. Filter Out | B32: CE02 | C32: Storage Echannel CCC | D32: No Assigned L6 | E32: Storage | F32: Storage | G32: Y | H32: APJ | I32: China | J32: 0.629 | K32: =B32&"_"&C32 -> CE02_Storage Echannel CCC | M32: Chen Zhou | N32: 8 | O32: ESG | P32: Inactive
A33: 1. Filter Out | B33: CG Comp | C33: Global Compellent Capgemini | D33: No Assigned L6 | G33: Y | K33: =B33&"_"&C33 -> CG Comp_Global Compellent Capgemini | O33: ESG | P33: Inactive
A34: 1. Filter Out | B34: CGEQ | C34: GLOBAL Equallogic Capgemini | D34: Copeland, Jessica | E34: Storage | G34: Y | K34: =B34&"_"&C34 -> CGEQ_GLOBAL Equallogic Capgemini | O34: ESG | P34: Inactive
A35: 1. Filter Out | B35: CGGC | C35: Global Compellent Capgemini | D35: Copeland, Jessica | G35: Y | K35: =B35&"_"&C35 -> CGGC_Global Compellent Capgemini | O35: ESG | P35: Inactive
A36: 1. Filter Out | B36: CGVE | C36: GLOBAL VNXe Capgemini | D36: Copeland, Jessica | G36: Y | K36: =B36&"_"&C36 -> CGVE_GLOBAL VNXe Capgemini | O36: ESG | P36: Inactive
A37: 1. Filter Out | B37: CT13 | C37: CTE CCC | D37: No Assigned L6 | E37: CTE | F37: CTE | G37: Y | H37: Global | I37: Global | J37: 0.633 | K37: =B37&"_"&C37 -> CT13_CTE CCC | M37: Chen Zhou | N37: 14 | O37: ESG | P37: Inactive
A38: 1. Filter Out | B38: CT15 | C38: CTE JPN | D38: Johnson, Meghan | E38: CTE | F38: CTE | G38: Y | H38: Global | I38: Global | J38: 0.633 | K38: =B38&"_"&C38 -> CT15_CTE JPN | M38: Chen Zhou | N38: 14 | O38: ESG | P38: Inactive
A39: 1. Filter Out | B39: CT16 | C39: CTE KOR | D39: No Assigned L6 | E39: CTE | F39: CTE | G39: Y | H39: Global | I39: Global | J39: 0.633 | K39: =B39&"_"&C39 -> CT16_CTE KOR | N39: 14 | O39: ESG | P39: Inactive
A40: 1. Filter Out | B40: CT18 | C40: CTE SA | D40: No Assigned L6 | E40: CTE | F40: CTE | G40: Y | H40: Global | I40: Global | J40: 0.633 | K40: =B40&"_"&C40 -> CT18_CTE SA | M40: Chen Zhou | N40: 7 | O40: ESG | P40: Inactive
...

Sheet AR
B3: Raghaw | F3: Sarthak
B4: Action | C4: Code | F4: Capacity code | G4: Combined Queue Name | H4: New_Capacity code | I4: New_Combined Queue Name
B5: Missing | C5: GC21 | D5: ESG | F5: IS34 | G5: APJ HES MIDRANGE | H5: GS05 | I5: Global HES Midrange FL
B6: Missing | C6: GS03 | D6: ESG | F6: IS61 | G6: EMEA HES MIDRANGE
B7: Missing | C7: GS04 | D7: ESG | F7: IU43 | G7: NAMER HES MIDRANGE
B8: Missing | C8: GC22 | F8: IS14 | G8: APJ HES Connectivity | H8: GC22 | I8: Global Connectivity
B9: Missing | C9: HE12 | F9: IS41 | G9: EMEA HES Connectivity
B10: Missing | C10: GS05 | F10: IU23 | G10: NAMER HES Connectivity
B11: Fix | C11: GC23 | F11: IS32 | G11: APJ HES SymmSW | H11: GC24 | I11: Global Symmetrix SW
B12: Missing | C12: GC24 | F12: IU41 | G12: NAMER HES SymmSW
B13: Missing | C13: BL17 | F13: IS59 | G13: EMEA HES SymmSW
B14: Missing | C14: GH23 | F14: IS36 | G14: APJ HES Vplex | H14: GH23 | I14: Global Vplex Backline
F15: IS63 | G15: EMEA HES Vplex
F16: IU45 | G16: NAMER HES Vplex
F17: GH22 | G17: GLOBAL HES MIDRANGE | H17: BL17 | I17: GLOBAL HES MIDRANGE Backline
F18: GH24 | G18: GLOBAL HES XtremIO
F19: IS64 | G19: EMEA HES XtremIO
F20: IS21 | G20: APJ HES Integrated_Software | H20: HE12 | I20: Global Integrated Software
F21: IS48 | G21: EMEA HES Integrated_Software | H21: HE12 | I21: Global Integrated Software
F22: IU30 | G22: NAMER HES Integrated_Software | H22: HE12 | I22: Global Integrated Software

Sheet CQNs Merged_Split
B2: Old | D2: New
B3: Old CQN Code | C3: Old CQN Name | D3: New CQN Code | E3: New CQN Name
B4: BPS1 | C4: Brazil Powerstore | D4: BT02 | E4: Brazil Midrange
B5: RPS1 | C5: MMCLA Powerstore | D5: BT03 | E5: MMCLA Midrange
B6: IU16 | C6: LATAM HES MIDRANGE | D6: BT02 | E6: Brazil Midrange
B7: NE07 | C7: Networking Basic US | D7: BT04 | E7: Global Networking English
B8: NE20 | C8: Networking ProSupport US | D8: BT04 | E8: Global Networking English | F8: IU16 | G8: LATAM HES MIDRANGE
B9: MY11 | C9: Networking Pro Core SA | D9: BT04 | E9: Global Networking English
B10: AZ09 | C10: Networking ProSupport ANZ | D10: BT04 | E10: Global Networking English
B11: GB13 | C11: UKI Networking (CWD) | D11: BT04 | E11: Global Networking English
B12: EC34 | C12: EC ProSupp Server CEE (HAL) | D12: BT06 | E12: EC Compute CEE RUA
B13: EC21 | C13: EC RUS Enterprise (HAL) | D13: BT06 | E13: EC Compute CEE RUA
B14: PG01 | C14: POR ProSupp Server (MTP) | D14: BT07 | E14: SER Compute Iberian
B15: SP09 | C15: SPA ProSupp Server (MTP) | D15: BT07 | E15: SER Compute Iberian
B16: SP04 | C16: SPA Basic Enterprise (CAS) | D16: BT07 | E16: SER Compute Iberian
B17: FR05 | C17: FRA Basic Enterprise (CAS) | D17: BT08 | E17: SER Server French
B18: FR06 | C18: FRA Modular (MTP) | D18: BT08 | E18: SER Server French
B19: FR09 | C19: FRA ProSupport Server (CAS) | D19: BT08 | E19: SER Server French
B20: FR11 | C20: FRA ProSupport Plus Server (MTP) | D20: BT08 | E20: SER Server French
... B103: IS64 | C103: EMEA HES XtremIO | D103: BL17 | E103: GLOBAL HES MIDRANGE Backline
B104: CC12 | C104: Social Media CCC | D104: CC29 | E104: CCC CNS Mandarin | F104: WIP
B105: BT10 | C105: CCC CNS Mandarin Voice | D105: CC29 | E105: CCC CNS Mandarin | F105: WIP
B106: CE03 | C106: CCC CNS Mandarin Email | D106: CC29 | E106: CCC CNS Mandarin | F106: WIP
B107: AZ11 | C107: Storage ProSupport ANZ | E107: Need to Split between GP01 and GM01 | F107: WIP
B108: MY14 | C108: Storage ProSupport SA | F108: WIP
B109: KR05 | C109: KOR Compute Basic Korean | D109: KR14 | E109: Korea CNS | F109: WIP
B110: KR12 | C110: KOR Compute Upsell Korean | D110: KR14 | E110: Korea CNS | F110: WIP
B111: KR13 | C111: KOR Networking Upsell Korean | D111: KR14 | E111: Korea CNS | F111: WIP
B112: IS37 | C112: APJ HES XtremIO | D112: AP23 | E112: APJ HES MIDRANGE Japanese | F112: WIP
B113: IS11 | C113: APJ DPD AVAMAR | E113: APJ DPD Japanese
B114: IS15 | C114: APJ DPD DataDomain | E114: APJ DPD Japanese
B115: IS23 | C115: APJ DPD Networker | E115: APJ DPD Japanese
B116: GH11 | C116: GLOBAL DPD RecoverPoint | E116: APJ DPD Japanese

Sheet Sheet4
C3: AP26 | D3: =VLOOKUP(C3,$L$3:$M$212,2,FALSE) -> #N/A | L3: CC12 | M3: Social Media CCC
C4: AZ09 | D4: =VLOOKUP(C4,$L$3:$M$212,2,FALSE) -> #N/A | L4: CT23 | M4: GLOBAL HES BSAFE
C5: AZ10 | D5: =VLOOKUP(C5,$L$3:$M$212,2,FALSE) -> Server ProSupport ANZ | L5: CT24 | M5: HCS Global DSE
C6: AZ16 | D6: =VLOOKUP(C6,$L$3:$M$212,2,FALSE) -> Enterprise ANZ AOH | L6: CT25 | M6: Global Compute Hardware
C7: BT02 | D7: =VLOOKUP(C7,$L$3:$M$212,2,FALSE) -> #N/A | L7: CT27 | M7: Global Compute Software
C8: BT03 | D8: =VLOOKUP(C8,$L$3:$M$212,2,FALSE) -> #N/A | L8: CT30 | M8: Global Networking
C9: BT05 | D9: =VLOOKUP(C9,$L$3:$M$212,2,FALSE) -> EMEA Server Upsell English | L9: CT37 | M9: APJ HES CST Japanese
C10: BZ14 | D10: =VLOOKUP(C10,$L$3:$M$212,2,FALSE) -> #N/A | L10: CT68 | M10: RPS Proactive Systems Maintenance
C11: CC12 | D11: =VLOOKUP(C11,$L$3:$M$212,2,FALSE) -> Social Media CCC | L11: CT69 | M11: Social Media English
C12: CM03 | D12: =VLOOKUP(C12,$L$3:$M$212,2,FALSE) -> #N/A | L12: GC12 | M12: E2E Quality Coach
C13: CT24 | D13: =VLOOKUP(C13,$L$3:$M$212,2,FALSE) -> HCS Global DSE | L13: GC13 | M13: GIST Quality Coach
C14: CT27 | D14: =VLOOKUP(C14,$L$3:$M$212,2,FALSE) -> Global Compute Software | L14: GC14 | M14: Licensing Quality Coach
... C123: WM05 | D123: =VLOOKUP(C123,$L$3:$M$212,2,FALSE) -> APJ WFM | L123: TH07 | M123: Enterprise Pro/Core TH
L124: VN03 | M124: Enterprise Pro/Core VN
L125: AP10 | M125: APJ UDS PowerScale Chinese
L126: AP11 | M126: APJ UDS PowerScale Japanese
L127: AP12 | M127: APJ DPD AVAMAR Chinese
L128: AP13 | M128: APJ HES Connectivity Chinese
L129: AP14 | M129: APJ DPD DataDomain Chinese
L130: AP15 | M130: HCS APJ VxRail Chinese
L131: AP16 | M131: HCS APJ VxRail Japanese
L132: AP17 | M132: APJ HES Integrated_Software Chinese
L133: AP18 | M133: APJ DPD Networker Chinese
L134: AP19 | M134: APJ HES Symmetrix Chinese
L135: AP20 | M135: APJ HES Symmetrix Japanese
... L212: RL15 | M212: HCS LATAM MMCLA VxRail

Sheet Sheet5
D5: 1 | E5: 2 | F5: 3
D6: AZ10 | E6: Server ProSupport ANZ | F6: =VLOOKUP(D6,UniqueCCOQueueCodes!$A$379:$T$505,20,FALSE) -> #N/A
D7: AZ16 | E7: Enterprise ANZ AOH | F7: =VLOOKUP(D7,UniqueCCOQueueCodes!$A$379:$T$505,20,FALSE) -> #N/A
D8: BT05 | E8: EMEA Server Upsell English | F8: =VLOOKUP(D8,UniqueCCOQueueCodes!$A$379:$T$505,20,FALSE) -> #N/A
D9: CC12 | E9: Social Media CCC | F9: =VLOOKUP(D9,UniqueCCOQueueCodes!$A$379:$T$505,20,FALSE) -> #N/A
D10: CT24 | E10: HCS Global DSE | F10: =VLOOKUP(D10,UniqueCCOQueueCodes!$A$379:$T$505,20,FALSE) -> #N/A
D11: CT27 | E11: Global Compute Software | F11: =VLOOKUP(D11,UniqueCCOQueueCodes!$A$379:$T$505,20,FALSE) -> Not Planned
D12: CT29 | E12: HCS Global Vmware | F12: =VLOOKUP(D12,UniqueCCOQueueCodes!$A$379:$T$505,20,FALSE) -> #N/A
D13: CT68 | E13: RPS Proactive Systems Maintenance | F13: =VLOOKUP(D13,UniqueCCOQueueCodes!$A$379:$T$505,20,FALSE) -> #N/A
D14: CT69 | E14: Social Media English | F14: =VLOOKUP(D14,UniqueCCOQueueCodes!$A$379:$T$505,20,FALSE) -> Not Planned
D15: EG13 | E15: HCS Global Cloud Solutions | F15: =VLOOKUP(D15,UniqueCCOQueueCodes!$A$379:$T$505,20,FALSE) -> #N/A
D16: GB11 | E16: ENG Modular (CWD) | F16: =VLOOKUP(D16,UniqueCCOQueueCodes!$A$379:$T$505,20,FALSE) -> #N/A
D17: GB16 | E17: ENG ProSupp Server 247 (CWD) | F17: =VLOOKUP(D17,UniqueCCOQueueCodes!$A$379:$T$505,20,FALSE) -> #N/A
... D78: WM05 | E78: APJ WFM | F78: =VLOOKUP(D78,UniqueCCOQueueCodes!$A$379:$T$505,20,FALSE) -> Not Planned

Sheet Sheet6
C5: CT29 | D5: HCS Global Vmware | E5: HES | F5: GS01
C6: EG13 | D6: HCS Global Cloud Solutions | E6: HES | F6: GS01
C7: GH06 | D7: GLOBAL DPD DPSolutions | E7: HES | F7: GH06
C8: GH15 | D8: HCS Global Solutions | E8: HES | F8: GS02
C9: GH22 | D9: GLOBAL HES MIDRANGE | E9: HES | F9: BL17
C10: GH24 | D10: GLOBAL HES XtremIO | E10: HES | F10: BL17
C11: IS14 | D11: APJ HES Connectivity | E11: HES | F11: GC22
C12: IS21 | D12: APJ HES Integrated_Software | E12: HES | F12: HE12
C13: IS31 | D13: APJ HES Symmetrix | E13: HES | F13: GC23
C14: IS32 | D14: APJ HES SymmSW | E14: HES | F14: GC24
C15: IS34 | D15: APJ HES MIDRANGE | E15: HES | F15: GS05
C16: IS36 | D16: APJ HES Vplex | E16: HES | F16: GC24
... C29: IU45 | D29: NAMER HES Vplex | E29: HES | F29: GC24

Sheet Sheet2
A1: Flag | B1: Y
A4: LOB Alignment | B4: L5 | C4: Resource Region
A5: Avamar | B5: Punch, Patrick | C5: EMEA
C6: Global
C7: LATAM
C8: NAMER
B9: Yap, Diane | C9: APJ
C10: India
A11: Cloudboost | B11: Punch, Patrick | C11: Global
A12: Connectivity | B12: Whitney, Rich | C12: EMEA
C13: Global
C14: NAMER
B15: Yap, Diane | C15: APJ
C16: India
A17: Datadomain | B17: Punch, Patrick | C17: EMEA
C18: Global
C19: LATAM
C20: NAMER
B21: Yap, Diane | C21: APJ
C22: India
A23: DLM | B23: Whitney, Rich | C23: Global
A24: DP Solutions | B24: Yap, Diane | C24: APJ
A25: DPA | B25: Punch, Patrick | C25: Global
A26: DPADSRT | B26: Punch, Patrick | C26: Global
A27: DPSolutions | B27: Punch, Patrick | C27: Global
B28: Yap, Diane | C28: India
A29: Hyperconverged | B29: D'Arcy, Mark | C29: EMEA
C30: Global
C31: LATAM
C32: NAMER
B33: Yap, Diane | C33: APJ
C34: India
A35: Integrated_Software | B35: Whitney, Rich | C35: EMEA
C36: Global
C37: NAMER
B38: Yap, Diane | C38: APJ
C39: India
A40: Isilon | B40: Punch, Patrick | C40: EMEA
C41: Global
C42: LATAM
...

Sheet Sheet3
B1: CCOQueueAbbr | C1: CCOQueueCode
B2: Not Assigned | C2: Not Assigned
B3: Not Assigned | C3: Not Assigned
B4: Not Assigned | C4: Not Assigned
B5: Not Assigned | C5: Not Assigned
B6: Not Assigned | C6: Not Assigned
B7: Not Assigned | C7: Not Assigned
B8: Not Assigned | C8: Not Assigned
B9: Not Assigned | C9: Not Assigned
B10: Not Assigned | C10: Not Assigned
B11: NF42 | C11: SSO Non-Frontline
B12: Not Assigned | C12: Not Assigned
... B10814: Not Assigned | C10814: Not Assigned

Sheet Attrition
A1: Resource Region | B1: Quarterly Attrition
A2: APJ | B2: 0.0086107922
A3: EMEA | B3: 0.013363029
A4: Global | B4: 0.012025655
A5: LATAM | B5: 0.0081081081
A6: NAMER | B6: 0.033227848

Sheet TeamToQueueMap
A1: oracle_prem_team_nm | B1: epicenter_cco_queue_code | C1: epicenter_cco_queue_desc | D1: Planned
A2: AM_ASE_57_WS_SANFRANCISCO_L_C | E2: =VLOOKUP(B2,UniqueCCOQueueCodes!A:F,6,0) -> #N/A
A3: AM_ASE_57_WS_SEATTLE-WA_L_A | E3: =VLOOKUP(B3,UniqueCCOQueueCodes!A:F,6,0) -> #N/A
A4: AM_ASE_57_WS_SEATTLE-WA_M_A | E4: =VLOOKUP(B4,UniqueCCOQueueCodes!A:F,6,0) -> #N/A
A5: AM_ASE_64_CN_COLMBIA-SC_S_A | E5: =VLOOKUP(B5,UniqueCCOQueueCodes!A:F,6,0) -> #N/A
A6: AM_ASE_64_CN_MIAMI-FL_L_A | E6: =VLOOKUP(B6,UniqueCCOQueueCodes!A:F,6,0) -> #N/A
A7: AM_ASE_65_CN_CHICAGO-IL_L_A | E7: =VLOOKUP(B7,UniqueCCOQueueCodes!A:F,6,0) -> #N/A
A8: APJ_ASE_42_GC_Taiwan_L_A | E8: =VLOOKUP(B8,UniqueCCOQueueCodes!A:F,6,0) -> #N/A
A9: APJ_AVAMAR_GS_A | B9: HE36 | C9: HES Global AVAMAR | D9: =VLOOKUP(B9,UniqueCCOQueueCodes!$A$2:$F$554,4,FALSE) -> DPD | E9: =VLOOKUP(B9,UniqueCCOQueueCodes!A:F,6,0) -> Y
A10: APJ_AVAMAR_GS_B | B10: HE36 | C10: HES Global AVAMAR | D10: =VLOOKUP(B10,UniqueCCOQueueCodes!$A$2:$F$554,4,FALSE) -> DPD | E10: =VLOOKUP(B10,UniqueCCOQueueCodes!A:F,6,0) -> Y
A11: APJ_AVAMAR_GS_C | B11: HE36 | C11: HES Global AVAMAR | D11: =VLOOKUP(B11,UniqueCCOQueueCodes!$A$2:$F$554,4,FALSE) -> DPD | E11: =VLOOKUP(B11,UniqueCCOQueueCodes!A:F,6,0) -> Y
A12: APJ_Connectivity_GS_A | B12: HE29 | C12: HES Global Connectivity | D12: =VLOOKUP(B12,UniqueCCOQueueCodes!$A$2:$F$554,4,FALSE) -> Primary | E12: =VLOOKUP(B12,UniqueCCOQueueCodes!A:F,6,0) -> Y
A13: APJ_Connectivity_GS_B | B13: HE29 | C13: HES Global Connectivity | D13: =VLOOKUP(B13,UniqueCCOQueueCodes!$A$2:$F$554,4,FALSE) -> Primary | E13: =VLOOKUP(B13,UniqueCCOQueueCodes!A:F,6,0) -> Y
A14: APJ_Connectivity_GS_C | B14: HE29 | C14: HES Global Connectivity | D14: =VLOOKUP(B14,UniqueCCOQueueCodes!$A$2:$F$554,4,FALSE) -> Primary | E14: =VLOOKUP(B14,UniqueCCOQueueCodes!A:F,6,0) -> Y
A15: APJ_Converged_GS_C | B15: CT19 | C15: GLOBAL CONVERGED | D15: =VLOOKUP(B15,UniqueCCOQueueCodes!$A$2:$F$554,4,FALSE) -> GNCS | E15: =VLOOKUP(B15,UniqueCCOQueueCodes!A:F,6,0) -> Y
A16: APJ_Converged_GS_E | B16: CT19 | C16: GLOBAL CONVERGED | D16: =VLOOKUP(B16,UniqueCCOQueueCodes!$A$2:$F$554,4,FALSE) -> GNCS | E16: =VLOOKUP(B16,UniqueCCOQueueCodes!A:F,6,0) -> Y
A17: APJ_DataDomain_GS_A | B17: HE38 | C17: HES Global DATADomain | D17: =VLOOKUP(B17,UniqueCCOQueueCodes!$A$2:$F$554,4,FALSE) -> DPD | E17: =VLOOKUP(B17,UniqueCCOQueueCodes!A:F,6,0) -> Y
A18: APJ_DataDomain_GS_B | B18: HE38 | C18: HES Global DATADomain | D18: =VLOOKUP(B18,UniqueCCOQueueCodes!$A$2:$F$554,4,FALSE) -> DPD | E18: =VLOOKUP(B18,UniqueCCOQueueCodes!A:F,6,0) -> Y
A19: APJ_DLM_GS_A | B19: HE26 | C19: HES Global DLM | D19: =VLOOKUP(B19,UniqueCCOQueueCodes!$A$2:$F$554,4,FALSE) -> Primary | E19: =VLOOKUP(B19,UniqueCCOQueueCodes!A:F,6,0) -> Y
A20: APJ_DPA_GS_A | B20: HE42 | C20: HES Global DPA | D20: =VLOOKUP(B20,UniqueCCOQueueCodes!$A$2:$F$554,4,FALSE) -> DPD | E20: =VLOOKUP(B20,UniqueCCOQueueCodes!A:F,6,0) -> Y
... A39: APJ_RecoverPoint_GS_C | B39: HE39 | C39: HES Global RecoverPoint | D39: =VLOOKUP(B39,UniqueCCOQueueCodes!$A$2:$F$554,4,FALSE) -> DPD | E39: =VLOOKUP(B39,UniqueCCOQueueCodes!A:F,6,0) -> Y
A40: APJ_S&AS_AS_ANZ_A | D40: =VLOOKUP(B40,UniqueCCOQueueCodes!$A$2:$F$554,4,FALSE) -> #N/A | E40: =VLOOKUP(B40,UniqueCCOQueueCodes!A:F,6,0) -> #N/A
A41: APJ_S&AS_AS_CHINA_A | D41: =VLOOKUP(B41,UniqueCCOQueueCodes!$A$2:$F$554,4,FALSE) -> #N/A | E41: =VLOOKUP(B41,UniqueCCOQueueCodes!A:F,6,0) -> #N/A
A42: APJ_S&AS_AS_JAPAN_A | D42: =VLOOKUP(B42,UniqueCCOQueueCodes!$A$2:$F$554,4,FALSE) -> #N/A | E42: =VLOOKUP(B42,UniqueCCOQueueCodes!A:F,6,0) -> #N/A
A43: APJ_S&AS_CORE_JAPAN_A | D43: =VLOOKUP(B43,UniqueCCOQueueCodes!$A$2:$F$554,4,FALSE) -> #N/A | E43: =VLOOKUP(B43,UniqueCCOQueueCodes!A:F,6,0) -> #N/A
A44: APJ_SAM_A | D44: =VLOOKUP(B44,UniqueCCOQueueCodes!$A$2:$F$554,4,FALSE) -> #N/A | E44: =VLOOKUP(B44,UniqueCCOQueueCodes!A:F,6,0) -> #N/A
A45: APJ_SCALEIO_PowerFlex_GS_A | B45: HE12 | C45: HES Global Integrated Software | D45: =VLOOKUP(B45,UniqueCCOQueueCodes!$A$2:$F$554,4,FALSE) -> Primary | E45: =VLOOKUP(B45,UniqueCCOQueueCodes!A:F,6,0) -> Y
A46: APJ_SCALEIO_PowerFlex_GS_B | B46: HE12 | C46: HES Global Integrated Software | D46: =VLOOKUP(B46,UniqueCCOQueueCodes!$A$2:$F$554,4,FALSE) -> Primary | E46: =VLOOKUP(B46,UniqueCCOQueueCodes!A:F,6,0) -> Y
A47: APJ_SCALEIO_PowerFlex_GS_C | B47: HE12 | C47: HES Global Integrated Software | D47: =VLOOKUP(B47,UniqueCCOQueueCodes!$A$2:$F$554,4,FALSE) -> Primary | E47: =VLOOKUP(B47,UniqueCCOQueueCodes!A:F,6,0) -> Y
A48: APJ_Solutions_GS_A | B48: HE30 | C48: HES Global Solutions | D48: =VLOOKUP(B48,UniqueCCOQueueCodes!$A$2:$F$554,4,FALSE) -> GNCS | E48: =VLOOKUP(B48,UniqueCCOQueueCodes!A:F,6,0) -> Y
A49: APJ_SOURCEONE_GS_A | B49: GH12 | C49: GLOBAL DPD SOURCEONE | D49: =VLOOKUP(B49,UniqueCCOQueueCodes!$A$2:$F$554,4,FALSE) -> DPD | E49: =VLOOKUP(B49,UniqueCCOQueueCodes!A:F,6,0) -> Y
A50: APJ_Symm_GS_A | B50: HE22 | C50: HES Global Symmetrix | D50: =VLOOKUP(B50,UniqueCCOQueueCodes!$A$2:$F$554,4,FALSE) -> Primary | E50: =VLOOKUP(B50,UniqueCCOQueueCodes!A:F,6,0) -> Y
A51: APJ_Symm_GS_B | B51: HE22 | C51: HES Global Symmetrix | D51: =VLOOKUP(B51,UniqueCCOQueueCodes!$A$2:$F$554,4,FALSE) -> Primary | E51: =VLOOKUP(B51,UniqueCCOQueueCodes!A:F,6,0) -> Y
A52: APJ_Symm_GS_C | B52: HE22 | C52: HES Global Symmetrix | D52: =VLOOKUP(B52,UniqueCCOQueueCodes!$A$2:$F$554,4,FALSE) -> Primary | E52: =VLOOKUP(B52,UniqueCCOQueueCodes!A:F,6,0) -> Y
A53: APJ_Symm_GS_D | B53: HE23 | C53: HES Global SymmSW | D53: =VLOOKUP(B53,UniqueCCOQueueCodes!$A$2:$F$554,4,FALSE) -> Primary | E53: =VLOOKUP(B53,UniqueCCOQueueCodes!A:F,6,0) -> Y
A54: APJ_VNX_Midrange_GS_A | B54: GH22 | C54: GLOBAL HES MIDRANGE | D54: =VLOOKUP(B54,UniqueCCOQueueCodes!$A$2:$F$554,4,FALSE) -> Midrange | E54: =VLOOKUP(B54,UniqueCCOQueueCodes!A:F,6,0) -> Y
A55: APJ_VNX_Midrange_GS_B | B55: GH22 | C55: GLOBAL HES MIDRANGE | D55: =VLOOKUP(B55,UniqueCCOQueueCodes!$A$2:$F$554,4,FALSE) -> Midrange | E55: =VLOOKUP(B55,UniqueCCOQueueCodes!A:F,6,0) -> Y
A56: APJ_VNX_Midrange_Recovery_A | B56: GH22 | C56: GLOBAL HES MIDRANGE | D56: =VLOOKUP(B56,UniqueCCOQueueCodes!$A$2:$F$554,4,FALSE) -> Midrange | E56: =VLOOKUP(B56,UniqueCCOQueueCodes!A:F,6,0) -> Y
... A68: BNG_Connectivity_Connectrix_A | B68: HE29 | C68: HES Global Connectivity | D68: =VLOOKUP(B68,UniqueCCOQueueCodes!$A$2:$F$554,4,FALSE) -> Primary | E68: =VLOOKUP(B68,UniqueCCOQueueCodes!A:F,6,0) -> Y
A69: BNG_CSTLIC_B | D69: =VLOOKUP(B69,UniqueCCOQueueCodes!$A$2:$F$554,4,FALSE) -> #N/A | E69: =VLOOKUP(B69,UniqueCCOQueueCodes!A:F,6,0) -> #N/A
...

Sheet Utilz Targets
A1: - | B1: APJ | C1: 0.629 | D1: - | G1: - | J1: - | M1: - | P1: - | S1: - | V1: - | W1: All
B2: Japan | C2: 0.582
B3: China | C3: 0.639
B4: India | C4: 0.629
B5: EMEA | C5: 0.617
B6: NAMER | C6: 0.648 | H6: EMEA | I6: 0.623
B7: Global | C7: 0.633 | H7: Cork | I7: 0.613 | J7: 0.613
B8: LATAM | C8: 0.643 | H8: Egy | I8: 0.621 | J8: 0.621
I9: =AVERAGE(I6:I8) -> 0.619 | J9: =AVERAGE(J6:J8) -> 0.617
